ERROR    services.route_service:route_service.py:35 Маршрут c таким ID 1 уже существует.