ERROR    services.travel_service:travel_service.py:36 Путешествие c таким ID 1 уже существует.