ERROR    services.directory_route_service:directory_route_service.py:31 Справочник маршрутов c таким ID 1 уже существует.